Workbook

Sheet Run
A1: run_label | B1: testId | C1: passed | D1: hallucination | E1: route | F1: model | G1: latencyMs | H1: promptTokens | I1: completionTokens | J1: traceId | K1: output | L1: fullOutput | M1: riskRelevanceScore | N1: riskRelevancePass | O1: riskRelevanceReason | P1: unsupportedItems | Q1: judgeModel | R1: judgeTokens
A2: Run 2 - gpt-4o-mini - after Orchestrator fix | B2: T1 | C2: TRUE | D2: FALSE | E2: plan | F2: gpt-4o-mini-2024-07-18 | G2: 6187 | H2: 918 | I2: 603 | J2: 185b2e70b3ecfcb2300ce71874d9e979 | K2: # AI Adoption Project Plan for ABCDE Ltd. ## Project Summary ABCDE Ltd., a mid-sized enterprise specializing in logistics and supply chain solutions, is initiating an AI adoption project aimed at enhancing operational efficiency, improving customer experience, and driving data-driven decision-makin
A3: Run 2 - gpt-4o-mini - after Orchestrator fix | B3: T2 | C3: TRUE | D3: FALSE | E3: clarify | J3: 346663edcd53057dd38af84708c5dd79 | K3: This request does not have enough detail. To build a plan I need: the project scope, the goals, the deliverables, the timeline and the team size.
A4: Run 2 - gpt-4o-mini - after Orchestrator fix | B4: T3 | C4: TRUE | D4: FALSE | E4: risk | F4: gpt-4o-mini-2024-07-18 | G4: 5743 | H4: 1434 | I4: 617 | J4: 5b43e1fc1846f8fff262ab89bd07322b | K4: | Risk ID | Category | Risk Challenge | Impact | Mitigation Strategy | |---------|--------------------------------|-------------------------------------------------|--
A5: Run 2 - gpt-4o-mini - after Orchestrator fix | B5: T4 | C5: TRUE | D5: FALSE | E5: clarify | J5: 8b24e61e5b44d5a3998b996c671fd4b4 | K5: This request does not have enough detail. To assess risks I need: the project description or scope, the timeline, the domain or technology, and the team or stakeholders.
A6: Run 2 - gpt-4o-mini - after Orchestrator fix | B6: T5 | C6: TRUE | D6: FALSE | E6: status | F6: gpt-4o-mini-2024-07-18 | G6: 2692 | H6: 812 | I6: 243 | J6: 178b20128f944acd14342b3d77e4ff7b | K6: **Weekly Status Report** **As-of Date:** 2026-04-20 **Overall Health:** Amber - There are two tasks marked as "To Do," and one task is flagged "At risk." **Counts by Status:** Done: 0 In Progress: 2 To Do: 2 Blocked: 0 Total: 4 **Tasks Grouped by Status:** **In Progress:** - T
A7: Run 2 - gpt-4o-mini - after Orchestrator fix | B7: T6 | C7: TRUE | D7: FALSE | E7: clarify | J7: b9a0006b6aaf4cbb6061fa5be62d22cc | K7: This request does not have enough detail. No task data is available for this request, so I cannot report status. Please share the task board export (CSV) or a task list with statuses.
A8: Run 2 - gpt-4o-mini - after Orchestrator fix | B8: T7 | C8: TRUE | D8: FALSE | E8: risk | F8: gpt-4o-mini-2024-07-18 | G8: 2578 | H8: 1433 | I8: 215 | J8: b48025351e84030869d44e14422426a5 | K8: 1. **Risk ID:** R06 **Category:** Cost Overruns **Impact:** Budget constraints and project delays **Mitigation:** Set realistic budget and build in contingency funds **Reason:** The task T010 (Collect historical demand data) is still to do, which may lead to underestimating AI de
A9: Run 2 - gpt-4o-mini - after Orchestrator fix | B9: T8 | C9: TRUE | D9: FALSE | E9: milestones | F9: gpt-4o-mini-2024-07-18 | G9: 2238 | H9: 1057 | I9: 193 | J9: 839c9cb3fe335f54e90acfa76a5b3f5c | K9: Here are the flagged tasks that are blocked or at risk: 1. **Blocked Task** - **Task ID:** T024 - **Task Name:** Security review of AI infrastructure - **Status:** Blocked - **Due Date:** 2026-05-26 - **Flag:** Blocked - **Reason:** Waiting for security team availability - **Su
A10: Run 2 - gpt-4o-mini - after Orchestrator fix | B10: T9 | C10: TRUE | D10: FALSE | E10: clarify | J10: 64ca21fcf24746aced06f4a42305ec9a | K10: This request does not have enough detail. To build a plan I need: the project scope, the goals, the deliverables, the timeline and the team size.
A11: Run 2 - gpt-4o-mini - after Orchestrator fix | B11: T10 | C11: TRUE | D11: FALSE | E11: status | F11: gpt-4o-mini-2024-07-18 | G11: 1110 | H11: 2421 | I11: 37 | J11: 847f6366c535f85a3ffa221bda97f120 | K11: Done 5, In Progress 3, To Do 16, Blocked 1, Total 25. The Blocked task is T024: Security review of AI infrastructure. As-of date: 2026-04-20. Sources: project_description.txt, project_timeline.csv, project_risks.csv, sample_task_board.csv.
A12: Run 2 - gpt-4o-mini - after Orchestrator fix | B12: T11 | C12: TRUE | D12: FALSE | E12: milestones | F12: gpt-4o-mini-2024-07-18 | G12: 1378 | H12: 1056 | I12: 65 | J12: 5cf458b39a4a4b913bb0de4642759807 | K12: The upcoming milestones in the next 2 weeks are: 1. Current systems audit report - Due by 2026-04-21 2. Gap analysis report - Due by 2026-04-21 3. Final list of prioritized use cases with success criteria - Due by 2026-05-05 As-of date: 2026-04-20. Sources: project_description.txt, project_timelin
A13: Run 2 - gpt-4o-mini - after Orchestrator fix | B13: T12 | C13: TRUE | D13: FALSE | E13: status | F13: gpt-4o-mini-2024-07-18 | G13: 3069 | H13: 711 | I13: 238 | J13: b082ab04711a3dfdf71b5370686c3e1a | K13: Subject: Sprint 2 Progress Update - ABCDE Ltd. AI Adoption Project Dear Stakeholders, As of April 20, 2026, I am pleased to provide you with an update on the progress of Sprint 2 for the ABCDE Ltd. AI Adoption Project. **Progress by Task:** - **T004: Audit existing data infrastructure** - Status:
A14: Run 3 - gpt-4o-mini - T11 prompt fix | B14: T1 | C14: TRUE | D14: FALSE | E14: plan | F14: gpt-4o-mini-2024-07-18 | G14: 4926 | H14: 918 | I14: 606 | J14: 3d9b0efa2cd3b9cfbf5fdf4317a5e4e6 | K14: # AI Adoption Project Plan for ABCDE Ltd. ## Project Summary ABCDE Ltd., a mid-sized enterprise specializing in logistics and supply chain solutions, is initiating an AI adoption project aimed at enhancing operational efficiency, improving customer experience, and driving data-driven decision-makin | L14: # AI Adoption Project Plan for ABCDE Ltd. ## Project Summary ABCDE Ltd., a mid-sized enterprise specializing in logistics and supply chain solutions, is initiating an AI adoption project aimed at enhancing operational efficiency, improving customer experience, and driving data-driven decision-making. The project will integrate AI-powered tools into core business functions such as demand forecasting, route optimization, inventory management, and customer support. The initiative will be executed in phases, starting with an assessment of current workflows and data infrastructure, followed by pilot implementations in targeted departments. ## Goals - Reduce delivery delays by 15% - Lower operational costs by 10% - Improve service responsiveness ## Phases Table | Phase | Weeks | Key Activities | Milestones | End Date | |---------------------------|--------|---------------------------------------------------------|-----------------------------------------------------|-------------| | Project Initiation | 1-2 | Define project scope; Form cross-functional team; Initial stakeholder meeting | Project charter signed off; Team structure finalized | 2026-04-10 | | Current State Analysis | 3-4 | Assess existing processes & systems; Identify data sources & gaps | Current systems audit report; Gap analysis report | 2026-04-21 | | Use Case Selection | 5-6 | Shortlist priority AI use cases (forecasting, route optimization) | Final list of prioritized use cases with success criteria | 2026-05-05 | | Pilot Design | 7-10 | Data collection & preparation; Model design and development | Working prototype models; Data pipelines established | 2026-06-02 | | Pilot Implementation | 11-14 | Deploy AI models in test environments; Monitor performance | Pilot results report; User feedback and performance metrics | 2026-06-16 | | Evaluation & Iteration | 15-16 | Evaluate pilot outcomes; Adjust models as needed | Updated models and process refinements | 2026-06-30 | | Full Deployment | 17-22 | Scale AI models across selected departments; Train staff | Full production rollout; Training sessions completed | 2026-07-21 | | Monitoring & Review | 23-24 | Continuous performance monitoring; Final project review | Project closure report; Recommendations for future scaling | 2026-08-04 | ## Timeline Overview The project will span a total of 24 weeks, starting from April 10, 2026, and concluding on August 4, 2026. Each phase is designed to build upon the previous one, ensuring a structured approach to AI adoption. ## Assumptions and Gaps - Proposed, not in source: Specific team sizes and roles for the cross-functional task force. - Proposed, not in source: Detailed budget allocation for each phase of the project. ## Sources - Project description provided by ABCDE Ltd. As-of date: 2026-04-20. Sources: project_description.txt, project_timeline.csv, project_risks.csv, sample_task_board.csv.
A15: Run 3 - gpt-4o-mini - T11 prompt fix | B15: T2 | C15: TRUE | D15: FALSE | E15: clarify | J15: d4dbdb6a3e4b4d05bc4562dc438fe93a | K15: This request does not have enough detail. To build a plan I need: the project scope, the goals, the deliverables, the timeline and the team size. | L15: This request does not have enough detail. To build a plan I need: the project scope, the goals, the deliverables, the timeline and the team size.
A16: Run 3 - gpt-4o-mini - T11 prompt fix | B16: T3 | C16: TRUE | D16: FALSE | E16: risk | F16: gpt-4o-mini-2024-07-18 | G16: 5068 | H16: 1434 | I16: 604 | J16: 7a48c39a830e2af448bff2f204345583 | K16: | Risk ID | Category | Risk Challenge | Impact | Mitigation Strategy | |---------|--------------------------------|-------------------------------------------------|-- | L16: | Risk ID | Category | Risk Challenge | Impact | Mitigation Strategy | |---------|--------------------------------|-------------------------------------------------|------------------------------------------------|---------------------------------------------------------| | R01 | Data Quality & Availability | Incomplete or unstructured data | Poor model performance and inaccurate outcomes | Perform early data audits and implement robust data governance | | R02 | Integration Issues | Difficulty integrating AI with legacy systems | Delays in deployment and operational disruptions | Plan integration roadmap and use APIs/middleware | | R03 | Talent & Skills Gap | Lack of internal AI/ML expertise | Overreliance on external vendors and slow progress | Provide staff training and hire specialized talent | | R04 | Change Resistance | Employees resist adopting AI-driven workflows | Low adoption and reduced ROI | Strong change management and early engagement | | R05 | Ethical & Legal Concerns | Risks of biased models or data privacy violations | Legal repercussions and reputational damage | Involve legal early and implement fairness checks | | R06 | Cost Overruns | Underestimation of AI development costs | Budget constraints and project delays | Set realistic budget and build in contingency funds | | R07 | Unrealistic Expectations | Stakeholders expect immediate ROI | Disillusionment and loss of support | Align expectations and show quick wins | | R08 | Model Performance Drift | AI models lose accuracy over time | Incorrect decisions and trust erosion | Regular retraining cycles and monitoring dashboards | | R09 | Security Vulnerabilities | AI models targeted by adversarial attacks | Data breaches and operational risks | Adopt AI security best practices and penetration testing | | R10 | Vendor Lock-in | Overdependence on a specific AI platform | Flexibility loss and future switching costs | Favor open standards and negotiate flexible vendor terms | ### Top Risks and Why 1. **R06 - Cost Overruns**: The task "Vendor evaluation for ML platform" (T009) is still to do, which may lead to underestimating costs. 2. **R03 - Talent & Skills Gap**: The task "Staff training program" (T020) is still to do, indicating a lack of internal expertise. 3. **R01 - Data Quality & Availability**: The task "Identify data gaps and quality issues" (T006) is in progress, highlighting potential data challenges. 4. **R05 - Ethical & Legal Concerns**: The task "Legal review of data usage" (T025) is in progress, which may expose legal risks. 5. **R04 - Change Resistance**: The task "Staff training program" (T020) is still to do, which may lead to resistance in adopting AI workflows. ### Sources - Risks and mitigation strategies were derived from the provided risk list. - Task statuses were referenced from the provided task list. As-of date: 2026-04-20. Sources: project_description.txt, project_timeline.csv, project_risks.csv, sample_task_board.csv.
A17: Run 3 - gpt-4o-mini - T11 prompt fix | B17: T4 | C17: TRUE | D17: FALSE | E17: clarify | J17: cbb74a04f390117f352c6a2b54436c26 | K17: This request does not have enough detail. To assess risks I need: the project description or scope, the timeline, the domain or technology, and the team or stakeholders. | L17: This request does not have enough detail. To assess risks I need: the project description or scope, the timeline, the domain or technology, and the team or stakeholders.
A18: Run 3 - gpt-4o-mini - T11 prompt fix | B18: T5 | C18: TRUE | D18: FALSE | E18: status | F18: gpt-4o-mini-2024-07-18 | G18: 2990 | H18: 812 | I18: 246 | J18: 63913ba29f138820e589d9c1aa1dd3e8 | K18: **Weekly Status Report** **As-of Date:** 2026-04-20 **Overall Health:** Amber - There are two tasks marked as "To Do," and one task is flagged "At risk." **Counts by Status:** - Done: 0 - In Progress: 2 - To Do: 2 - Blocked: 0 - Total: 4 **Tasks Grouped by Status:** **In Progres | L18: **Weekly Status Report** **As-of Date:** 2026-04-20 **Overall Health:** Amber - There are two tasks marked as "To Do," and one task is flagged "At risk." **Counts by Status:** - Done: 0 - In Progress: 2 - To Do: 2 - Blocked: 0 - Total: 4 **Tasks Grouped by Status:** **In Progress:** - T007: Shortlist AI use cases - T025: Legal review of data usage **To Do:** - T008: Define success criteria for each use case - T009: Vendor evaluation for ML platform **Blocked Items:** - None **Upcoming Milestones:** - Current State Analysis (Due: 2026-04-21) - Activities: Assess existing processes & systems; Identify data sources & gaps - Milestones: Current systems audit report; Gap analysis report **Risks or Actions Needed:** - T008: Define success criteria for each use case is flagged "At risk" and needs attention to ensure timely completion. --- This concludes the weekly status report. As-of date: 2026-04-20. Sources: project_description.txt, project_timeline.csv, project_risks.csv, sample_task_board.csv.
A19: Run 3 - gpt-4o-mini - T11 prompt fix | B19: T6 | C19: TRUE | D19: FALSE | E19: clarify | J19: ed7cbc8638e475422f732e8e709e0d6a | K19: This request does not have enough detail. No task data is available for this request, so I cannot report status. Please share the task board export (CSV) or a task list with statuses. | L19: This request does not have enough detail. No task data is available for this request, so I cannot report status. Please share the task board export (CSV) or a task list with statuses.
A20: Run 3 - gpt-4o-mini - T11 prompt fix | B20: T7 | C20: TRUE | D20: FALSE | E20: risk | F20: gpt-4o-mini-2024-07-18 | G20: 2640 | H20: 1433 | I20: 213 | J20: b4120701d48f0c4a1189ed45b360b890 | K20: 1. **Risk ID:** R06 **Category:** Cost Overruns **Impact:** Budget constraints and project delays **Mitigation:** Set realistic budget and build in contingency funds **Reason:** The task T010 (Collect historical demand data) is still to do, which may lead to underestimating AI de | L20: 1. **Risk ID:** R06 **Category:** Cost Overruns **Impact:** Budget constraints and project delays **Mitigation:** Set realistic budget and build in contingency funds **Reason:** The task T010 (Collect historical demand data) is still to do, which may lead to underestimating AI development costs. 2. **Risk ID:** R01 **Category:** Data Quality & Availability **Impact:** Poor model performance and inaccurate outcomes **Mitigation:** Perform early data audits and implement robust data governance **Reason:** The task T006 (Identify data gaps and quality issues) is in progress, highlighting potential data quality challenges. 3. **Risk ID:** R05 **Category:** Ethical & Legal Concerns **Impact:** Legal repercussions and reputational damage **Mitigation:** Involve legal early and implement fairness checks **Reason:** The task T025 (Legal review of data usage) is in progress, indicating ongoing concerns about data ethics and compliance. As-of date: 2026-04-20. Sources: project_description.txt, project_timeline.csv, project_risks.csv, sample_task_board.csv.
A21: Run 3 - gpt-4o-mini - T11 prompt fix | B21: T8 | C21: TRUE | D21: FALSE | E21: milestones | F21: gpt-4o-mini-2024-07-18 | G21: 1993 | H21: 1113 | I21: 180 | J21: eabb14b15a66e3920829d37f0e0ff7c5 | K21: 1. **Blocked Tasks:** - **Task ID:** T024 - **Name:** Security review of AI infrastructure - **Status:** Blocked - **Due Date:** 2026-05-26 - **Flag:** Blocked - **Reason:** waiting for security team availability - **Suggested Action:** Follow up with the security te | L21: 1. **Blocked Tasks:** - **Task ID:** T024 - **Name:** Security review of AI infrastructure - **Status:** Blocked - **Due Date:** 2026-05-26 - **Flag:** Blocked - **Reason:** waiting for security team availability - **Suggested Action:** Follow up with the security team to confirm availability and expedite the review process. 2. **At Risk Tasks:** - **Task ID:** T008 - **Name:** Define success criteria for each use case - **Status:** To Do - **Due Date:** 2026-05-02 - **Flag:** At risk - **Reason:** 12 days to due - **Suggested Action:** Prioritize this task to ensure success criteria are defined before the deadline. As-of date: 2026-04-20. Sources: project_description.txt, project_timeline.csv, project_risks.csv, sample_task_board.csv.
A22: Run 3 - gpt-4o-mini - T11 prompt fix | B22: T9 | C22: TRUE | D22: FALSE | E22: clarify | J22: f86ea517d9c39c0adbb799fed07c101c | K22: This request does not have enough detail. To build a plan I need: the project scope, the goals, the deliverables, the timeline and the team size. | L22: This request does not have enough detail. To build a plan I need: the project scope, the goals, the deliverables, the timeline and the team size.
A23: Run 3 - gpt-4o-mini - T11 prompt fix | B23: T10 | C23: TRUE | D23: FALSE | E23: status | F23: gpt-4o-mini-2024-07-18 | G23: 992 | H23: 2421 | I23: 35 | J23: 6168039fbf07ec8e5d35d76534699320 | K23: Done 5, In Progress 3, To Do 16, Blocked 1, Total 25. Blocked task: T024 Security review of AI infrastructure. As-of date: 2026-04-20. Sources: project_description.txt, project_timeline.csv, project_risks.csv, sample_task_board.csv. | L23: Done 5, In Progress 3, To Do 16, Blocked 1, Total 25. Blocked task: T024 Security review of AI infrastructure. As-of date: 2026-04-20. Sources: project_description.txt, project_timeline.csv, project_risks.csv, sample_task_board.csv.
A24: Run 3 - gpt-4o-mini - T11 prompt fix | B24: T11 | C24: TRUE | D24: FALSE | E24: milestones | F24: gpt-4o-mini-2024-07-18 | G24: 1388 | H24: 1112 | I24: 47 | J24: 900a4b569255b8bfdbec527d6fb9cf8c | K24: Milestones in the next 2 weeks: 1. Current systems audit report 2. Gap analysis report Next milestone after this window: Final list of prioritized use cases with success criteria (due 2026-05-05). As-of date: 2026-04-20. Sources: project_description.txt, project_timeline.csv, project_risks.csv, sa | L24: Milestones in the next 2 weeks: 1. Current systems audit report 2. Gap analysis report Next milestone after this window: Final list of prioritized use cases with success criteria (due 2026-05-05). As-of date: 2026-04-20. Sources: project_description.txt, project_timeline.csv, project_risks.csv, sample_task_board.csv.
A25: Run 3 - gpt-4o-mini - T11 prompt fix | B25: T12 | C25: TRUE | D25: FALSE | E25: status | F25: gpt-4o-mini-2024-07-18 | G25: 3110 | H25: 711 | I25: 249 | J25: bda81c6e4250ae22b7749860e7e605fc | K25: Subject: Sprint 2 Progress Update - ABCDE Ltd. AI Adoption Project Dear Stakeholders, As of April 20, 2026, I am pleased to provide you with an update on the progress of Sprint 2 for the ABCDE Ltd. AI Adoption Project. **Progress Overview:** - **Task T004: Audit existing data infrastructure** - S | L25: Subject: Sprint 2 Progress Update - ABCDE Ltd. AI Adoption Project Dear Stakeholders, As of April 20, 2026, I am pleased to provide you with an update on the progress of Sprint 2 for the ABCDE Ltd. AI Adoption Project. **Progress Overview:** - **Task T004: Audit existing data infrastructure** - Status: Done (Assignee: Priya Nair) - **Task T005: Map current logistics workflows** - Status: Done (Assignee: James Wong) - **Task T006: Identify data gaps and quality issues** - Status: In Progress (Assignee: Priya Nair) **Next Steps for Open Tasks:** - For **Task T006: Identify data gaps and quality issues**, Priya Nair is currently working on the gap analysis report, which is due on April 21, 2026. This task is flagged for monitoring as it is still in progress. Overall, we have completed 2 tasks and have 1 task currently in progress. The project is on track, with no blocked items at this time. Thank you for your continued support. Best regards, Mira Project Assistant Nexora Pvt. Ltd. As-of date: 2026-04-20. Sources: project_description.txt, project_timeline.csv, project_risks.csv, sample_task_board.csv.
A26: Run 4 - gpt-4o-mini - with risk judge | B26: T1 | C26: TRUE | D26: FALSE | E26: plan | F26: gpt-4o-mini-2024-07-18 | G26: 5407 | H26: 918 | I26: 613 | J26: 5be90b6b5694f430699a5d664f61fda2 | K26: # AI Adoption Project Plan for ABCDE Ltd. ## Project Summary ABCDE Ltd., a mid-sized enterprise specializing in logistics and supply chain solutions, is initiating an AI adoption project aimed at enhancing operational efficiency, improving customer experience, and driving data-driven decision-makin | L26: # AI Adoption Project Plan for ABCDE Ltd. ## Project Summary ABCDE Ltd., a mid-sized enterprise specializing in logistics and supply chain solutions, is initiating an AI adoption project aimed at enhancing operational efficiency, improving customer experience, and driving data-driven decision-making. The project will integrate AI-powered tools into core business functions such as demand forecasting, route optimization, inventory management, and customer support. The initiative will be executed in phases, starting with an assessment of current workflows and data infrastructure, followed by pilot implementations in targeted departments. ## Goals - Reduce delivery delays by 15% - Lower operational costs by 10% - Improve service responsiveness ## Phases Table | Phase | Weeks | Key Activities | Milestones | End Date | |---------------------------|---------|---------------------------------------------------------|-----------------------------------------------------|--------------| | Project Initiation | 1-2 | Define project scope; Form cross-functional team; Initial stakeholder meeting | Project charter signed off; Team structure finalized | 2026-04-10 | | Current State Analysis | 3-4 | Assess existing processes & systems; Identify data sources & gaps | Current systems audit report; Gap analysis report | 2026-04-21 | | Use Case Selection | 5-6 | Shortlist priority AI use cases (forecasting, route optimization) | Final list of prioritized use cases with success criteria | 2026-05-05 | | Pilot Design | 7-10 | Data collection & preparation; Model design and development | Working prototype models; Data pipelines established | 2026-06-02 | | Pilot Implementation | 11-14 | Deploy AI models in test environments; Monitor performance | Pilot results report; User feedback and performance metrics | 2026-06-16 | | Evaluation & Iteration | 15-16 | Evaluate pilot outcomes; Adjust models as needed | Updated models and process refinements | 2026-06-30 | | Full Deployment | 17-22 | Scale AI models across selected departments; Train staff | Full production rollout; Training sessions completed | 2026-07-21 | | Monitoring & Review | 23-24 | Continuous performance monitoring; Final project review | Project closure report; Recommendations for future scaling | 2026-08-04 | ## Timeline Overview The project will span a total of 24 weeks, starting from the initiation phase and concluding with the monitoring and review phase. Each phase is designed to build upon the previous one, ensuring a structured approach to AI adoption. ## Assumptions and Gaps - Proposed, not in source: Specific team sizes and roles for the cross-functional team. - Proposed, not in source: Detailed budget for the project phases. - Proposed, not in source: Specific tools and technologies to be used for AI implementation. ## Sources - Project description provided by ABCDE Ltd. As-of date: 2026-04-20. Sources: project_description.txt, project_timeline.csv, project_risks.csv, sample_task_board.csv. | M26: n/a | N26: n/a
A27: Run 4 - gpt-4o-mini - with risk judge | B27: T2 | C27: TRUE | D27: FALSE | E27: clarify | J27: 838d10895fd5cf257871db62df4758aa | K27: This request does not have enough detail. To build a plan I need: the project scope, the goals, the deliverables, the timeline and the team size. | L27: This request does not have enough detail. To build a plan I need: the project scope, the goals, the deliverables, the timeline and the team size. | M27: n/a | N27: n/a
A28: Run 4 - gpt-4o-mini - with risk judge | B28: T3 | C28: TRUE | D28: FALSE | E28: risk | F28: gpt-4o-mini-2024-07-18 | G28: 5435 | H28: 1434 | I28: 548 | J28: c2909017633e196947f03c1823b835c3 | K28: | Risk ID | Category | Risk Challenge | Impact | Mitigation Strategy | |---------|--------------------------------|-------------------------------------------------|-- | L28: | Risk ID | Category | Risk Challenge | Impact | Mitigation Strategy | |---------|--------------------------------|-------------------------------------------------|------------------------------------------------|---------------------------------------------------------| | R01 | Data Quality & Availability | Incomplete or unstructured data | Poor model performance and inaccurate outcomes | Perform early data audits and implement robust data governance | | R02 | Integration Issues | Difficulty integrating AI with legacy systems | Delays in deployment and operational disruptions | Plan integration roadmap and use APIs/middleware | | R03 | Talent & Skills Gap | Lack of internal AI/ML expertise | Overreliance on external vendors and slow progress | Provide staff training and hire specialized talent | | R04 | Change Resistance | Employees resist adopting AI-driven workflows | Low adoption and reduced ROI | Strong change management and early engagement | | R05 | Ethical & Legal Concerns | Risks of biased models or data privacy violations | Legal repercussions and reputational damage | Involve legal early and implement fairness checks | | R06 | Cost Overruns | Underestimation of AI development costs | Budget constraints and project delays | Set realistic budget and build in contingency funds | | R07 | Unrealistic Expectations | Stakeholders expect immediate ROI | Disillusionment and loss of support | Align expectations and show quick wins | | R08 | Model Performance Drift | AI models lose accuracy over time | Incorrect decisions and trust erosion | Regular retraining cycles and monitoring dashboards | | R09 | Security Vulnerabilities | AI models targeted by adversarial attacks | Data breaches and operational risks | Adopt AI security best practices and penetration testing | | R10 | Vendor Lock-in | Overdependence on a specific AI platform | Flexibility loss and future switching costs | Favor open standards and negotiate flexible vendor terms | ### Top Risks and Why 1. **R06 - Cost Overruns**: The task of setting a realistic budget and building in contingency funds is crucial, especially as the project progresses and costs may be underestimated (T024 - Security review of AI infrastructure is blocked). 2. **R05 - Ethical & Legal Concerns**: The ongoing legal review of data usage (T025) highlights the importance of addressing potential legal repercussions and reputational damage. 3. **R01 - Data Quality & Availability**: The task of identifying data gaps and quality issues (T006) is currently in progress, which directly relates to the risk of incomplete or unstructured data affecting model performance. ### Sources - Risks and mitigation strategies provided in the input. - Project tasks and their statuses. As-of date: 2026-04-20. Sources: project_description.txt, project_timeline.csv, project_risks.csv, sample_task_board.csv. | M28: 5 | N28: TRUE | O28: All risks and mitigations listed in Mira's answer are directly from the reference risk register and are highly relevant to the AI Adoption Project at ABCDE Ltd. | Q28: gpt-4o-mini-2024-07-18 | R28: 1281
A29: Run 4 - gpt-4o-mini - with risk judge | B29: T4 | C29: TRUE | D29: FALSE | E29: clarify | J29: b988f2615f41091bca05ca85ef9932bc | K29: This request does not have enough detail. To assess risks I need: the project description or scope, the timeline, the domain or technology, and the team or stakeholders. | L29: This request does not have enough detail. To assess risks I need: the project description or scope, the timeline, the domain or technology, and the team or stakeholders. | M29: n/a | N29: n/a
A30: Run 4 - gpt-4o-mini - with risk judge | B30: T5 | C30: TRUE | D30: FALSE | E30: status | F30: gpt-4o-mini-2024-07-18 | G30: 2453 | H30: 812 | I30: 241 | J30: 9ab909fd0fefd273c49ad7ccdaffea27 | K30: **Weekly Status Report** **As-of Date:** 2026-04-20 **Overall Health:** Amber - There are two tasks marked as "To Do," and one task is flagged "At risk." **Counts by Status:** Done: 0 In Progress: 2 To Do: 2 Blocked: 0 Total: 4 **Tasks Grouped by Status:** **In Progress:** - T | L30: **Weekly Status Report** **As-of Date:** 2026-04-20 **Overall Health:** Amber - There are two tasks marked as "To Do," and one task is flagged "At risk." **Counts by Status:** Done: 0 In Progress: 2 To Do: 2 Blocked: 0 Total: 4 **Tasks Grouped by Status:** **In Progress:** - T007: Shortlist AI use cases - T025: Legal review of data usage **To Do:** - T008: Define success criteria for each use case - T009: Vendor evaluation for ML platform **Blocked Items:** None **Upcoming Milestones:** - **Current State Analysis** (Due: 2026-04-21) - Activities: Assess existing processes & systems; Identify data sources & gaps - Milestones: Current systems audit report; Gap analysis report **Risks or Actions Needed:** - T008: Define success criteria for each use case is flagged "At risk" and needs attention to ensure timely completion. --- This concludes the weekly status report. As-of date: 2026-04-20. Sources: project_description.txt, project_timeline.csv, project_risks.csv, sample_task_board.csv. | M30: n/a | N30: n/a
A31: Run 4 - gpt-4o-mini - with risk judge | B31: T6 | C31: TRUE | D31: FALSE | E31: clarify | J31: 40792e07884b79c23783444e3ca22acc | K31: This request does not have enough detail. No task data is available for this request, so I cannot report status. Please share the task board export (CSV) or a task list with statuses. | L31: This request does not have enough detail. No task data is available for this request, so I cannot report status. Please share the task board export (CSV) or a task list with statuses. | M31: n/a | N31: n/a
A32: Run 4 - gpt-4o-mini - with risk judge | B32: T7 | C32: TRUE | D32: FALSE | E32: risk | F32: gpt-4o-mini-2024-07-18 | G32: 2383 | H32: 1433 | I32: 215 | J32: 7b7295509f9bed671b58d1ff7b205b77 | K32: 1. **Risk ID:** R06 **Category:** Cost Overruns **Impact:** Budget constraints and project delays **Mitigation:** Set realistic budget and build in contingency funds **Reason:** The task T010 (Collect historical demand data) is still to do, which may lead to underestimating AI de | L32: 1. **Risk ID:** R06 **Category:** Cost Overruns **Impact:** Budget constraints and project delays **Mitigation:** Set realistic budget and build in contingency funds **Reason:** The task T010 (Collect historical demand data) is still to do, which may lead to underestimating AI development costs. 2. **Risk ID:** R01 **Category:** Data Quality & Availability **Impact:** Poor model performance and inaccurate outcomes **Mitigation:** Perform early data audits and implement robust data governance **Reason:** The task T006 (Identify data gaps and quality issues) is in progress, highlighting potential data quality challenges. 3. **Risk ID:** R05 **Category:** Ethical & Legal Concerns **Impact:** Legal repercussions and reputational damage **Mitigation:** Involve legal early and implement fairness checks **Reason:** The task T025 (Legal review of data usage) is in progress, indicating ongoing concerns about compliance and ethical use of data. As-of date: 2026-04-20. Sources: project_description.txt, project_timeline.csv, project_risks.csv, sample_task_board.csv. | M32: 5 | N32: TRUE | O32: All identified risks are present in the reference risk register and the mitigations provided are appropriate for each risk. | Q32: gpt-4o-mini-2024-07-18 | R32: 943
A33: Run 4 - gpt-4o-mini - with risk judge | B33: T8 | C33: TRUE | D33: FALSE | E33: milestones | F33: gpt-4o-mini-2024-07-18 | G33: 1871 | H33: 1113 | I33: 180 | J33: 1ffd0df6b27e95b5d2152e98398c457f | K33: 1. **Blocked Tasks:** - **Task ID:** T024 - **Name:** Security review of AI infrastructure - **Status:** Blocked - **Due Date:** 2026-05-26 - **Flag:** Blocked - **Reason:** waiting for security team availability - **Suggested Action:** Follow up with the security te | L33: 1. **Blocked Tasks:** - **Task ID:** T024 - **Name:** Security review of AI infrastructure - **Status:** Blocked - **Due Date:** 2026-05-26 - **Flag:** Blocked - **Reason:** waiting for security team availability - **Suggested Action:** Follow up with the security team to confirm availability and expedite the review process. 2. **At Risk Tasks:** - **Task ID:** T008 - **Name:** Define success criteria for each use case - **Status:** To Do - **Due Date:** 2026-05-02 - **Flag:** At risk - **Reason:** 12 days to due - **Suggested Action:** Prioritize this task to ensure success criteria are defined before the deadline. As-of date: 2026-04-20. Sources: project_description.txt, project_timeline.csv, project_risks.csv, sample_task_board.csv. | M33: n/a | N33: n/a
A34: Run 4 - gpt-4o-mini - with risk judge | B34: T9 | C34: TRUE | D34: FALSE | E34: clarify | J34: 21ecc5b056215cf98855f1d203ccbe16 | K34: This request does not have enough detail. To build a plan I need: the project scope, the goals, the deliverables, the timeline and the team size. | L34: This request does not have enough detail. To build a plan I need: the project scope, the goals, the deliverables, the timeline and the team size. | M34: n/a | N34: n/a
A35: Run 4 - gpt-4o-mini - with risk judge | B35: T10 | C35: TRUE | D35: FALSE | E35: status | F35: gpt-4o-mini-2024-07-18 | G35: 937 | H35: 2421 | I35: 37 | J35: 9453063fae08cb7a10a943d1b1d2ae72 | K35: Done 5, In Progress 3, To Do 16, Blocked 1, Total 25. The Blocked task is T024: Security review of AI infrastructure. As-of date: 2026-04-20. Sources: project_description.txt, project_timeline.csv, project_risks.csv, sample_task_board.csv. | L35: Done 5, In Progress 3, To Do 16, Blocked 1, Total 25. The Blocked task is T024: Security review of AI infrastructure. As-of date: 2026-04-20. Sources: project_description.txt, project_timeline.csv, project_risks.csv, sample_task_board.csv. | M35: n/a | N35: n/a
A36: Run 4 - gpt-4o-mini - with risk judge | B36: T11 | C36: TRUE | D36: FALSE | E36: milestones | F36: gpt-4o-mini-2024-07-18 | G36: 1028 | H36: 1112 | I36: 47 | J36: c5e039f71bec229b3ff56702950dd6e6 | K36: Milestones in the next 2 weeks: 1. Current systems audit report 2. Gap analysis report Next milestone after this window: Final list of prioritized use cases with success criteria (due 2026-05-05). As-of date: 2026-04-20. Sources: project_description.txt, project_timeline.csv, project_risks.csv, sa | L36: Milestones in the next 2 weeks: 1. Current systems audit report 2. Gap analysis report Next milestone after this window: Final list of prioritized use cases with success criteria (due 2026-05-05). As-of date: 2026-04-20. Sources: project_description.txt, project_timeline.csv, project_risks.csv, sample_task_board.csv. | M36: n/a | N36: n/a
A37: Run 4 - gpt-4o-mini - with risk judge | B37: T12 | C37: TRUE | D37: FALSE | E37: status | F37: gpt-4o-mini-2024-07-18 | G37: 3001 | H37: 711 | I37: 221 | J37: a2c6e80f5fac5d075b7b6f0ae4427f2b | K37: Subject: Sprint 2 Progress Update - ABCDE Ltd. AI Adoption Project Dear Stakeholders, As of April 20, 2026, I am pleased to provide you with an update on the progress of Sprint 2 for the ABCDE Ltd. AI Adoption Project. **Progress by Task:** - **T004: Audit existing data infrastructure** - Status: | L37: Subject: Sprint 2 Progress Update - ABCDE Ltd. AI Adoption Project Dear Stakeholders, As of April 20, 2026, I am pleased to provide you with an update on the progress of Sprint 2 for the ABCDE Ltd. AI Adoption Project. **Progress by Task:** - **T004: Audit existing data infrastructure** - Status: Done (Assignee: Priya Nair) - **T005: Map current logistics workflows** - Status: Done (Assignee: James Wong) - **T006: Identify data gaps and quality issues** - Status: In Progress (Assignee: Priya Nair) **Next Steps for Open Tasks:** - For **T006: Identify data gaps and quality issues**, Priya Nair is currently working on the gap analysis report, which is due on April 21, 2026. Overall, we have completed 2 tasks, with 1 task still in progress. Thank you for your continued support. Best regards, Mira Project Assistant Nexora Pvt. Ltd. As-of date: 2026-04-20. Sources: project_description.txt, project_timeline.csv, project_risks.csv, sample_task_board.csv. | M37: n/a | N37: n/a
A38: Run 5 - gpt-4o-mini - stricter judge | B38: T1 | C38: TRUE | D38: FALSE | E38: plan | F38: gpt-4o-mini-2024-07-18 | G38: 6356 | H38: 918 | I38: 610 | J38: 6da62bc27fbc19e49a11a12d7f47d766 | K38: # AI Adoption Project Plan for ABCDE Ltd. ## Project Summary ABCDE Ltd., a mid-sized enterprise specializing in logistics and supply chain solutions, is initiating an AI adoption project aimed at enhancing operational efficiency, improving customer experience, and driving data-driven decision-makin | L38: # AI Adoption Project Plan for ABCDE Ltd. ## Project Summary ABCDE Ltd., a mid-sized enterprise specializing in logistics and supply chain solutions, is initiating an AI adoption project aimed at enhancing operational efficiency, improving customer experience, and driving data-driven decision-making. The project will integrate AI-powered tools into core business functions such as demand forecasting, route optimization, inventory management, and customer support. The initiative will be executed in phases, starting with an assessment of current workflows and data infrastructure, followed by pilot implementations in targeted departments. ## Goals - Reduce delivery delays by 15% - Lower operational costs by 10% - Improve service responsiveness ## Phases Table | Phase | Weeks | Key Activities | Milestones | End Date | |---------------------------|---------|-------------------------------------------------------|-----------------------------------------------------|-------------| | Project Initiation | 1-2 | Define project scope; Form cross-functional team; Initial stakeholder meeting | Project charter signed off; Team structure finalized | 2026-04-10 | | Current State Analysis | 3-4 | Assess existing processes & systems; Identify data sources & gaps | Current systems audit report; Gap analysis report | 2026-04-21 | | Use Case Selection | 5-6 | Shortlist priority AI use cases (forecasting, route optimization) | Final list of prioritized use cases with success criteria | 2026-05-05 | | Pilot Design | 7-10 | Data collection & preparation; Model design and development | Working prototype models; Data pipelines established | 2026-06-02 | | Pilot Implementation | 11-14 | Deploy AI models in test environments; Monitor performance | Pilot results report; User feedback and performance metrics | 2026-06-16 | | Evaluation & Iteration | 15-16 | Evaluate pilot outcomes; Adjust models as needed | Updated models and process refinements | 2026-06-30 | | Full Deployment | 17-22 | Scale AI models across selected departments; Train staff | Full production rollout; Training sessions completed | 2026-07-21 | | Monitoring & Review | 23-24 | Continuous performance monitoring; Final project review | Project closure report; Recommendations for future scaling | 2026-08-04 | ## Timeline Overview The project will span a total of 24 weeks, starting from the initiation phase and concluding with the monitoring and review phase. Each phase is designed to build upon the previous one, ensuring a structured approach to AI adoption. ## Assumptions and Gaps - Proposed, not in source: Specific team sizes and roles for the cross-functional team. - Proposed, not in source: Detailed budget for the project phases. - Proposed, not in source: Specific tools and technologies to be used for AI implementation. ## Sources - Project description provided by ABCDE Ltd. As-of date: 2026-04-20. Sources: project_description.txt, project_timeline.csv, project_risks.csv, sample_task_board.csv. | M38: n/a | N38: n/a
A39: Run 5 - gpt-4o-mini - stricter judge | B39: T2 | C39: TRUE | D39: FALSE | E39: clarify | J39: 1e5276a625ae7aa9dd1d0c1ec2ccaa9a | K39: This request does not have enough detail. To build a plan I need: the project scope, the goals, the deliverables, the timeline and the team size. | L39: This request does not have enough detail. To build a plan I need: the project scope, the goals, the deliverables, the timeline and the team size. | M39: n/a | N39: n/a
A40: Run 5 - gpt-4o-mini - stricter judge | B40: T3 | C40: TRUE | D40: FALSE | E40: risk | F40: gpt-4o-mini-2024-07-18 | G40: 7154 | H40: 1434 | I40: 609 | J40: ba6bd648d9013fae010619c35911e09d | K40: | Risk ID | Category | Risk Challenge | Impact | Mitigation Strategy | |---------|--------------------------------|-------------------------------------------------|-- | L40: | Risk ID | Category | Risk Challenge | Impact | Mitigation Strategy | |---------|--------------------------------|-------------------------------------------------|------------------------------------------------|---------------------------------------------------------| | R01 | Data Quality & Availability | Incomplete or unstructured data | Poor model performance and inaccurate outcomes | Perform early data audits and implement robust data governance | | R02 | Integration Issues | Difficulty integrating AI with legacy systems | Delays in deployment and operational disruptions | Plan integration roadmap and use APIs/middleware | | R03 | Talent & Skills Gap | Lack of internal AI/ML expertise | Overreliance on external vendors and slow progress | Provide staff training and hire specialized talent | | R04 | Change Resistance | Employees resist adopting AI-driven workflows | Low adoption and reduced ROI | Strong change management and early engagement | | R05 | Ethical & Legal Concerns | Risks of biased models or data privacy violations | Legal repercussions and reputational damage | Involve legal early and implement fairness checks | | R06 | Cost Overruns | Underestimation of AI development costs | Budget constraints and project delays | Set realistic budget and build in contingency funds | | R07 | Unrealistic Expectations | Stakeholders expect immediate ROI | Disillusionment and loss of support | Align expectations and show quick wins | | R08 | Model Performance Drift | AI models lose accuracy over time | Incorrect decisions and trust erosion | Regular retraining cycles and monitoring dashboards | | R09 | Security Vulnerabilities | AI models targeted by adversarial attacks | Data breaches and operational risks | Adopt AI security best practices and penetration testing | | R10 | Vendor Lock-in | Overdependence on a specific AI platform | Flexibility loss and future switching costs | Favor open standards and negotiate flexible vendor terms | ### Top Risks and Why 1. **R06 - Cost Overruns**: The task "Vendor evaluation for ML platform" (T009) is still to do, which may lead to underestimating costs. 2. **R01 - Data Quality & Availability**: The task "Identify data gaps and quality issues" (T006) is in progress, indicating potential data quality challenges. 3. **R05 - Ethical & Legal Concerns**: The task "Legal review of data usage" (T025) is in progress, highlighting the need to address legal risks early. 4. **R03 - Talent & Skills Gap**: The task "Staff training program" (T020) is to do, which suggests a current lack of internal expertise. 5. **R04 - Change Resistance**: The task "Strong change management and early engagement" is implied but not explicitly listed, indicating a need for proactive measures. ### Sources - Risks and mitigation strategies were derived from the provided risk list. - Task statuses were referenced to identify potential impacts on risk management. As-of date: 2026-04-20. Sources: project_description.txt, project_timeline.csv, project_risks.csv, sample_task_board.csv. | M40: 5 | N40: TRUE | O40: All risks and mitigations listed in Mira's answer are present in the reference risk register and are specifically relevant to the AI Adoption Project in logistics. | Q40: gpt-4o-mini-2024-07-18 | R40: 1373
...

Sheet Summary
A1: Run | B1: Tests | C1: Passed | D1: Pass rate | E1: Hallucinations | F1: Avg latency (ms) | G1: Judged tests | H1: Risk relevance pass rate | I1: Avg risk score | J1: Avg cost per request | K1: Cost per 100 requests: | L1: Notes
A2: Run 2 - gpt-4o-mini - after Orchestrator fix | B2: =COUNTIFS(Run!$A:$A,$A2) -> 12 | C2: =COUNTIFS(Run!$A:$A,$A2,Run!$C:$C,TRUE) -> 12 | D2: =IFERROR(C2/B2,"") -> 1 | E2: =COUNTIFS(Run!$A:$A,$A2,Run!$D:$D,TRUE) -> 0 | F2: =IFERROR(AVERAGEIFS(Run!$G:$G,Run!$A:$A,$A2),"") -> 3124.375 | G2: =COUNTIFS(Run!$A:$A,$A2,Run!$M:$M,">0") -> 0 | H2: =IF(G2=0,"n/a",COUNTIFS(Run!$A:$A,$A2,Run!$N:$N,TRUE)/G2) -> n/a | I2: =IF(G2=0,"n/a",AVERAGEIFS(Run!$M:$M,Run!$A:$A,$A2,Run!$M:$M,">0")) -> n/a | J2: $0.000319 | K2: $0.032 | L2: T11 false pass (extra 2026-05-05 milestone in window). Check tightened.
A3: Run 3 - gpt-4o-mini - T11 prompt fix | B3: =COUNTIFS(Run!$A:$A,$A3) -> 12 | C3: =COUNTIFS(Run!$A:$A,$A3,Run!$C:$C,TRUE) -> 12 | D3: =IFERROR(C3/B3,"") -> 1 | E3: =COUNTIFS(Run!$A:$A,$A3,Run!$D:$D,TRUE) -> 0 | F3: =IFERROR(AVERAGEIFS(Run!$G:$G,Run!$A:$A,$A3),"") -> 2888.375 | G3: =COUNTIFS(Run!$A:$A,$A3,Run!$M:$M,">0") -> 0 | H3: =IF(G3=0,"n/a",COUNTIFS(Run!$A:$A,$A3,Run!$N:$N,TRUE)/G3) -> n/a | I3: =IF(G3=0,"n/a",AVERAGEIFS(Run!$M:$M,Run!$A:$A,$A3,Run!$M:$M,">0")) -> n/a | J3: $0.000318 | K3: $0.032 | L3: T11 fixed with a prompt rule and a stricter check. 12/12.
A4: Run 4 - gpt-4o-mini - with risk judge | B4: =COUNTIFS(Run!$A:$A,$A4) -> 12 | C4: =COUNTIFS(Run!$A:$A,$A4,Run!$C:$C,TRUE) -> 12 | D4: =IFERROR(C4/B4,"") -> 1 | E4: =COUNTIFS(Run!$A:$A,$A4,Run!$D:$D,TRUE) -> 0 | F4: =IFERROR(AVERAGEIFS(Run!$G:$G,Run!$A:$A,$A4),"") -> 2814.375 | G4: =COUNTIFS(Run!$A:$A,$A4,Run!$M:$M,">0") -> 2 | H4: =IF(G4=0,"n/a",COUNTIFS(Run!$A:$A,$A4,Run!$N:$N,TRUE)/G4) -> 1 | I4: =IF(G4=0,"n/a",AVERAGEIFS(Run!$M:$M,Run!$A:$A,$A4,Run!$M:$M,">0")) -> 5 | J4: $0.000315 | K4: $0.032 | L4: Risk-relevance judge added (T3, T7). Langfuse evaluator agrees, 5/5.
A5: Run 5 - gpt-4o-mini - stricter judge | B5: =COUNTIFS(Run!$A:$A,$A5) -> 12 | C5: =COUNTIFS(Run!$A:$A,$A5,Run!$C:$C,TRUE) -> 12 | D5: =IFERROR(C5/B5,"") -> 1 | E5: =COUNTIFS(Run!$A:$A,$A5,Run!$D:$D,TRUE) -> 0 | F5: =IFERROR(AVERAGEIFS(Run!$G:$G,Run!$A:$A,$A5),"") -> 3471.75 | G5: =COUNTIFS(Run!$A:$A,$A5,Run!$M:$M,">0") -> 2 | H5: =IF(G5=0,"n/a",COUNTIFS(Run!$A:$A,$A5,Run!$N:$N,TRUE)/G5) -> 1 | I5: =IF(G5=0,"n/a",AVERAGEIFS(Run!$M:$M,Run!$A:$A,$A5,Run!$M:$M,">0")) -> 5 | J5: $0.00032 | K5: $0.03 | L5: Judge rule 8 added. Calibration: fake R11 scored 3 and 4 before and 2 and 2 after. Real answers stayed at 5, and the Langfuse evaluator agrees.
F7: Note: The 4 clarify tests (T2, T4, T6, T9) have no latency | J7: Note: Calculated from tokens (Runs 2 to 4), measured in Langfuse (Run 5). Judge calls excluded.

Sheet Known Limitations
A1: ID | B1: Test | C1: Finding | D1: Severity | E1: Why it wasn’t caught by the check | F1: Mitigation in place
A2: KL-1 | B2: T1 | C2: Intermittent: seen in Run 3, absent in Runs 4 and 5 (Run 2 output truncated). The plan states the project starts on 2026-04-10 and ends 2026-08-04 over 24 weeks. April 10 is the Phase 1 end date, not a start date, and the span is about 16 weeks. | D2: Medium (wrong date in a client-facing plan) | E2: Score only checks that all 8 phase names are present, not the prose dates. | F2: The human approval step: the PM reads the plan before it is emailed.
A3: KL-2 | B3: T12 | C3: Intermittent: seen in Run 3, absent in Runs 4 and 5 (Run 2 output truncated). The sprint update says "the project is on track, with no blocked items" while T024 is Blocked on the board (Sprint 5). The claim is true for Sprint 2 but overstated. | D3: Low to Medium (tone and overclaim) | E3: Score only checks that the right Sprint 2 tasks appear and that no Sprint 3+ tasks do. | F3: The human approval step. Also, the update is scoped to Sprint 2 by design.
A4: KL-3 | B4: T8 | C4: T006 (In Progress, due 2026-04-21) is not listed. It falls under “Watch” per the rule (In Progress due within 7 days), not “At risk”. | D4: Low (rule-consistent, but a reader might expect it) | E4: The expected list follows the at-risk rule, so the test passes. | F4: Document the Watch category. Optionally add it to the prompt later.
A5: KL-4 | B5: T11 | C5: Run 2 listed the 2026-05-05 milestone inside the 14-day window, which was wrong. The check was a false pass. It was fixed with a stricter check and a prompt rule in Run 3. | D5: Resolved | E5: The original check only looked for the two required deliverables. | F5: Fixed in Run 3. Keep the Run 2 row as evidence.
A6: KL-5 | B6: All | C6: Scoring is by code heuristics (IDs, counts, route, required phrases). It cannot judge the accuracy of the prose, which is how KL-1 and KL-2 got through. | D6: Design limitation | E6: n/a | F6: Risk relevance is judged by an LLM. Everything else relies on human review before sending.
A7: KL-6 | B7: T3, T7 | C7: The judge scores register fit, not reasoning quality. Run 5 T3 scored 5 although the R04 justification cites a task that does not exist (“implied but not explicitly listed”). Run 4 T3 linked R06 (Cost Overruns) to the blocked security task T024, which relates to security (R09), not cost, yet the judge still scored it 5 | D7: Low to Medium (weak justifications pass) | E7: The judge rubric and the unsupported-items check look at risk IDs and categories, not at the task links in the “why” text. | F7: The human approval step. Optional future check: verify every task ID in the justification against the task board.
A8: KL-7 | B8: All | C8: Model comparison not run. gpt-4.1-mini is blocked on the project’s OpenAI allow-list (403, project proj_mxTN…), in both n8n and Langfuse. The writer, the code-scored judge, and the Langfuse evaluator all run on gpt-4o-mini, so the judge is the same model family as the writer (self-preference risk). | D8: Design limitation | E8: Not a test failure. A platform access restriction. | F8: The calibration test (fake R11 scored 2 after rule 8) and the human approval step. Next step: ask the project owner to allow a second model, or add a second provider (it needs a BRD line, since OpenAI is the approved provider).
A9: KL-8 | B9: T3, T7 (risk judge) | C9: The judge catches register-fit defects but passes IDs-only answers, generic reasons and wrong task links | D9: Medium (judge validated for register fit only) | E9: Earlier runs were 12/12 on good answers, and a lenient judge looks identical to a good one. | F9: The human approval step. Judge v2 was evaluated offline and recommended, but it is not deployed in Mira Eval. Runs 2 to 5 used v1. Code ID checks, judge-on-the-board and fine-tuning are listed as future work.
A10: KL-9 | B10: T3, T7 (risk judge) | C10: Judge v2 rule 9 misfires: it lists real task IDs (for example T006, T009, T024) as unsupported and fails good answers (K07, L03, L05). Rule 10 (IDs only) had no effect: K08 scored 5 in both versions. | D10: Low to Medium (causes extra human review, blocks nothing) | E10: The judge has no copy of the task board, and the model does not apply rules 9 and 10 reliably. | F10: Task-ID and completeness checks belong in code (planned). The human approval step already reviews every answer.
A11: KL-10 | B11: Chat, approval email | C11: Underscores in file names (for example project_timeline.csv) were turned into italics in the approved email, because the Markdown-to-HTML step treated the underscores as emphasis | D11: Low (display only) | E11: The eval workflow tests the draft text. It does not render the approved email. | F11: Fixed on 2026-10-22 with the “Middle Word Underscores” option on the To HTML node. Confirmed in the approved email.

Sheet Judge Calibration
A1: id | B1: request | C1: answer | D1: human_score_1to5 | E1: human_pass_yes_no | F1: human_notes
A2: J01 | B2: Generate a risk assessment for the AI Adoption Project at ABCDE Ltd. | C2: ### Top Risks and Why 1. **R06 - Cost Overruns**: The task "Vendor evaluation for ML platform" (T009) is still to do, which may lead to underestimating costs. 2. **R03 - Talent & Skills Gap**: The task "Staff training program" (T020) is still to do, indicating a lack of internal expertise. 3. **R01 - Data Quality & Availability**: The task "Identify data gaps and quality issues" (T006) is in progress, highlighting potential data challenges. 4. **R05 - Ethical & Legal Concerns**: The task "Legal review of data usage" (T025) is in progress, which may expose legal risks. 5. **R04 - Change Resistance**: The task "Staff training program" (T020) is still to do, which may lead to resistance in adopting AI workflows. | D2: 4 | E2: yes | F2: this answers the question
A3: J02 | B3: What are the top 3 risks for the ABCDE Ltd project based on the risk data? | C3: 1. **Risk ID:** R05 **Category:** Cost Overruns **Impact:** Budget constraints and project delays **Mitigation:** Set realistic budget and build in contingency funds **Reason:** The task T009 (Vendor evaluation for ML platform) is still to do. 2. **Risk ID:** R06 **Category:** Ethical & Legal Concerns **Impact:** Legal repercussions and reputational damage **Mitigation:** Involve legal early and implement fairness checks **Reason:** The task T025 (Legal review of data usage) is in progress. 3. **Risk ID:** R01 **Category:** Data Quality & Availability **Impact:** Poor model performance and inaccurate outcomes **Mitigation:** Perform early data audits and implement robust data governance **Reason:** The task T006 (Identify data gaps and quality issues) is in progress. | D3: 2 | E3: no | F3: wrong categorization
A4: J03 | B4: What are the top 3 risks for the ABCDE Ltd project based on the risk data? | C4: The top three risks are R01, R05 and R06. | D4: 3 | E4: No | F4: No details
A5: J04 | B5: What are the top 3 risks for the ABCDE Ltd project based on the risk data? | C5: 1. **Risk ID:** R01 **Category:** Data Quality & Availability **Impact:** Poor model performance and inaccurate outcomes **Mitigation:** Perform early data audits and implement robust data governance **Reason:** The task T006 (Identify data gaps and quality issues) is in progress, highlighting potential data quality challenges. 2. **Risk ID:** R06 **Category:** Cost Overruns **Impact:** Budget constraints and project delays **Mitigation:** Set realistic budget and build in contingency funds **Reason:** The task T009 (Vendor evaluation for ML platform) is still to do, which may lead to underestimating costs. 3. **Risk ID:** R11 **Category:** Supply Chain Disruption **Impact:** Delayed deliveries across the network **Mitigation:** Add backup suppliers **Reason:** Supplier outages could delay the pilot. | D5: 2 | E5: no | F5: bit of manfacutured risk, halliculation
A6: J05 | B6: What are the top 3 risks for the ABCDE Ltd project based on the risk data? | C6: 1. **Risk ID:** R06 **Category:** Cost Overruns **Impact:** Budget constraints and project delays **Mitigation:** Set realistic budget and build in contingency funds **Reason:** Every project can run over budget. 2. **Risk ID:** R07 **Category:** Unrealistic Expectations **Impact:** Disillusionment and loss of support **Mitigation:** Align expectations and show quick wins **Reason:** Stakeholders in any project may expect too much. 3. **Risk ID:** R04 **Category:** Change Resistance **Impact:** Low adoption and reduced ROI **Mitigation:** Strong change management and early engagement **Reason:** People can resist change in any organisation. | D6: 2 | E6: no | F6: reasons doesn't make sense
A7: J06 | B7: What are the top 3 risks for the ABCDE Ltd project based on the risk data? | C7: 1. **Risk ID:** R09 **Category:** Security Vulnerabilities **Impact:** Data breaches and operational risks **Mitigation:** Adopt AI security best practices and penetration testing **Reason:** The task T024 (Security review of AI infrastructure) is blocked, leaving security exposure unaddressed. 2. **Risk ID:** R10 **Category:** Vendor Lock-in **Impact:** Flexibility loss and future switching costs **Mitigation:** Favor open standards and negotiate flexible vendor terms **Reason:** The task T009 (Vendor evaluation for ML platform) is still to do, so platform dependence is not yet assessed. 3. **Risk ID:** R01 **Category:** Data Quality & Availability **Impact:** Poor model performance and inaccurate outcomes **Mitigation:** Perform early data audits and implement robust data governance **Reason:** The task T006 (Identify data gaps and quality issues) is in progress, so data quality is not yet confirmed. | D7: 5 | E7: yes | F7: Answer is in tuned with the groundtruth
A8: J07 | B8: What are the top 3 risks for the ABCDE Ltd project based on the risk data? | C8: 1. **Risk ID:** R01 **Category:** Data Quality & Availability **Impact:** Poor model performance and inaccurate outcomes **Mitigation:** Perform early data audits and implement robust data governance **Reason:** The task T030 (Data lake migration) is delayed, which threatens data quality. 2. **Risk ID:** R05 **Category:** Ethical & Legal Concerns **Impact:** Legal repercussions and reputational damage **Mitigation:** Involve legal early and implement fairness checks **Reason:** The task T031 (GDPR audit) is blocked, so legal exposure is open. 3. **Risk ID:** R06 **Category:** Cost Overruns **Impact:** Budget constraints and project delays **Mitigation:** Set realistic budget and build in contingency funds **Reason:** The task T032 (Budget re-forecast) is overdue, which may hide cost overruns. | D8: 2 | E8: no | F8: Manfautured data, halliculation
A9: J08 | B9: What are the top 3 risks for the ABCDE Ltd project based on the risk data? | C9: 1. **Risk ID:** R01 **Category:** Data Quality & Availability **Impact:** Poor model performance and inaccurate outcomes **Mitigation:** Buy additional office chairs **Reason:** The task T006 (Identify data gaps and quality issues) is in progress. 2. **Risk ID:** R03 **Category:** Talent & Skills Gap **Impact:** Overreliance on external vendors and slow progress **Mitigation:** Schedule a team lunch **Reason:** Staff may lack AI expertise. 3. **Risk ID:** R09 **Category:** Security Vulnerabilities **Impact:** Data breaches and operational risks **Mitigation:** Repaint the warehouse **Reason:** The task T024 (Security review of AI infrastructure) is blocked. | D9: 2 | E9: no | F9: Mitigation plan is not in consistent with the groundtruth
